python -m unittest customer_console.py.TestOrderManagementSystem
E
======================================================================
ERROR: py (unittest.loader._FailedTest)
----------------------------------------------------------------------
AttributeError: module 'customer_console' has no attribute 'py'

----------------------------------------------------------------------
Ran 1 test in 0.000s

FAILED (errors=1)

obolo@Emmanuel MINGW64 ~/CollabU (master)
$ python -m unittest customer_console.TestOrderManagementSystem
EEEEEEEEEE
======================================================================
ERROR: test_add_order_duplicate (customer_console.TestOrderManagementSystem)
----------------------------------------------------------------------
Traceback (most recent call last):
  File "C:\Users\obolo\CollabU\customer_console.py", line 231, in test_add_order_duplicate
    save_orders([Order('001', 'John Doe', ['item1', 'item2'], True)],
TypeError: save_orders() got an unexpected keyword argument 'file_path'

======================================================================
ERROR: test_add_order_empty_items (customer_console.TestOrderManagementSystem)
----------------------------------------------------------------------
Traceback (most recent call last):
  File "C:\Users\obolo\CollabU\customer_console.py", line 239, in test_add_order_empty_items
    save_orders([], file_path=self.orders_file)
TypeError: save_orders() got an unexpected keyword argument 'file_path'

======================================================================
ERROR: test_add_order_valid (customer_console.TestOrderManagementSystem)
----------------------------------------------------------------------
Traceback (most recent call last):
  File "C:\Users\obolo\CollabU\customer_console.py", line 223, in test_add_order_valid
    save_orders([], file_path=self.orders_file)
TypeError: save_orders() got an unexpected keyword argument 'file_path'

======================================================================
ERROR: test_load_orders_corrupted (customer_console.TestOrderManagementSystem)
----------------------------------------------------------------------
Traceback (most recent call last):
  File "C:\Users\obolo\CollabU\customer_console.py", line 250, in test_load_orders_corrupted
    orders = load_orders(file_path=self.orders_file)
TypeError: load_orders() got an unexpected keyword argument 'file_path'

======================================================================
ERROR: test_load_orders_empty (customer_console.TestOrderManagementSystem)
----------------------------------------------------------------------
Traceback (most recent call last):
  File "C:\Users\obolo\CollabU\customer_console.py", line 164, in test_load_orders_empty
    orders = load_orders(file_path=self.orders_file)
TypeError: load_orders() got an unexpected keyword argument 'file_path'

======================================================================
ERROR: test_load_orders_single (customer_console.TestOrderManagementSystem)
----------------------------------------------------------------------
Traceback (most recent call last):
  File "C:\Users\obolo\CollabU\customer_console.py", line 169, in test_load_orders_single
    save_orders([Order('001', 'John Doe', ['item1', 'item2'], True)], file_path=self.orders_file)
TypeError: save_orders() got an unexpected keyword argument 'file_path'

======================================================================
ERROR: test_process_order_high_priority (customer_console.TestOrderManagementSystem)
----------------------------------------------------------------------
Traceback (most recent call last):
  File "C:\Users\obolo\CollabU\customer_console.py", line 203, in test_process_order_high_priority
    save_orders([Order('001', 'John Doe', ['item1', 'item2'], True)],
TypeError: save_orders() got an unexpected keyword argument 'file_path'

======================================================================
ERROR: test_process_order_non_priority (customer_console.TestOrderManagementSystem)
----------------------------------------------------------------------
Traceback (most recent call last):
  File "C:\Users\obolo\CollabU\customer_console.py", line 213, in test_process_order_non_priority
    save_orders([Order('001', 'John Doe', ['item1', 'item2'], False)],
TypeError: save_orders() got an unexpected keyword argument 'file_path'

======================================================================
ERROR: test_save_orders_multiple (customer_console.TestOrderManagementSystem)
----------------------------------------------------------------------
Traceback (most recent call last):
  File "C:\Users\obolo\CollabU\customer_console.py", line 180, in test_save_orders_multiple
    save_orders([Order('001', 'John Doe', ['item1', 'item2'], True),
TypeError: save_orders() got an unexpected keyword argument 'file_path'

======================================================================
ERROR: test_show_pending_orders (customer_console.TestOrderManagementSystem)
----------------------------------------------------------------------
Traceback (most recent call last):
  File "C:\Users\obolo\CollabU\customer_console.py", line 191, in test_show_pending_orders
    save_orders([Order('001', 'John Doe', ['item1', 'item2'], True),
TypeError: save_orders() got an unexpected keyword argument 'file_path'

----------------------------------------------------------------------
Ran 10 tests in 0.043s

FAILED (errors=10)